2023-02-09 01:34:44,407 ERROR: Exception on /api/search [GET] [in /mnt/c/Users/willw/Documents/GitHub/projet_photo/microblog/venv/lib/python3.11/site-packages/flask/app.py:1457]
Traceback (most recent call last):
  File "/mnt/c/Users/willw/Documents/GitHub/projet_photo/microblog/venv/lib/python3.11/site-packages/flask/app.py", line 2073, in wsgi_app
    response = self.full_dispatch_request()
               ^^^^^^^^^^^^^^^^^^^^^^^^^^^^
  File "/mnt/c/Users/willw/Documents/GitHub/projet_photo/microblog/venv/lib/python3.11/site-packages/flask/app.py", line 1518, in full_dispatch_request
    rv = self.handle_user_exception(e)
         ^^^^^^^^^^^^^^^^^^^^^^^^^^^^^
  File "/mnt/c/Users/willw/Documents/GitHub/projet_photo/microblog/venv/lib/python3.11/site-packages/flask/app.py", line 1516, in full_dispatch_request
    rv = self.dispatch_request()
         ^^^^^^^^^^^^^^^^^^^^^^^
  File "/mnt/c/Users/willw/Documents/GitHub/projet_photo/microblog/venv/lib/python3.11/site-packages/flask/app.py", line 1502, in dispatch_request
    return self.ensure_sync(self.view_functions[rule.endpoint])(**req.view_args)
           ^^^^^^^^^^^^^^^^^^^^^^^^^^^^^^^^^^^^^^^^^^^^^^^^^^^^^^^^^^^^^^^^^^^^^
  File "/mnt/c/Users/willw/Documents/GitHub/projet_photo/microblog/app/api/routes.py", line 36, in search
    return Response(json.dumps(set(values)), mimetype='application/json', cls=setEncoder)
                    ^^^^^^^^^^^^^^^^^^^^^^^
  File "/usr/lib/python3.11/json/__init__.py", line 231, in dumps
    return _default_encoder.encode(obj)
           ^^^^^^^^^^^^^^^^^^^^^^^^^^^^
  File "/usr/lib/python3.11/json/encoder.py", line 200, in encode
    chunks = self.iterencode(o, _one_shot=True)
             ^^^^^^^^^^^^^^^^^^^^^^^^^^^^^^^^^^
  File "/usr/lib/python3.11/json/encoder.py", line 258, in iterencode
    return _iterencode(o, 0)
           ^^^^^^^^^^^^^^^^^
  File "/usr/lib/python3.11/json/encoder.py", line 180, in default
    raise TypeError(f'Object of type {o.__class__.__name__} '
TypeError: Object of type set is not JSON serializable
2023-02-09 01:36:08,801 INFO: Microblog startup [in /mnt/c/Users/willw/Documents/GitHub/projet_photo/microblog/app/__init__.py:87]
2023-02-09 01:36:11,666 ERROR: Exception on /api/search [GET] [in /mnt/c/Users/willw/Documents/GitHub/projet_photo/microblog/venv/lib/python3.11/site-packages/flask/app.py:1457]
Traceback (most recent call last):
  File "/mnt/c/Users/willw/Documents/GitHub/projet_photo/microblog/venv/lib/python3.11/site-packages/flask/app.py", line 2073, in wsgi_app
    response = self.full_dispatch_request()
               ^^^^^^^^^^^^^^^^^^^^^^^^^^^^
  File "/mnt/c/Users/willw/Documents/GitHub/projet_photo/microblog/venv/lib/python3.11/site-packages/flask/app.py", line 1518, in full_dispatch_request
    rv = self.handle_user_exception(e)
         ^^^^^^^^^^^^^^^^^^^^^^^^^^^^^
  File "/mnt/c/Users/willw/Documents/GitHub/projet_photo/microblog/venv/lib/python3.11/site-packages/flask/app.py", line 1516, in full_dispatch_request
    rv = self.dispatch_request()
         ^^^^^^^^^^^^^^^^^^^^^^^
  File "/mnt/c/Users/willw/Documents/GitHub/projet_photo/microblog/venv/lib/python3.11/site-packages/flask/app.py", line 1502, in dispatch_request
    return self.ensure_sync(self.view_functions[rule.endpoint])(**req.view_args)
           ^^^^^^^^^^^^^^^^^^^^^^^^^^^^^^^^^^^^^^^^^^^^^^^^^^^^^^^^^^^^^^^^^^^^^
  File "/mnt/c/Users/willw/Documents/GitHub/projet_photo/microblog/app/api/routes.py", line 36, in search
    return Response(json.dumps(values), mimetype='application/json')
                    ^^^^^^^^^^^^^^^^^^
  File "/usr/lib/python3.11/json/__init__.py", line 231, in dumps
    return _default_encoder.encode(obj)
           ^^^^^^^^^^^^^^^^^^^^^^^^^^^^
  File "/usr/lib/python3.11/json/encoder.py", line 200, in encode
    chunks = self.iterencode(o, _one_shot=True)
             ^^^^^^^^^^^^^^^^^^^^^^^^^^^^^^^^^^
  File "/usr/lib/python3.11/json/encoder.py", line 258, in iterencode
    return _iterencode(o, 0)
           ^^^^^^^^^^^^^^^^^
  File "/usr/lib/python3.11/json/encoder.py", line 180, in default
    raise TypeError(f'Object of type {o.__class__.__name__} '
TypeError: Object of type set is not JSON serializable
2023-02-09 01:36:23,385 INFO: Microblog startup [in /mnt/c/Users/willw/Documents/GitHub/projet_photo/microblog/app/__init__.py:87]
2023-02-09 01:36:24,888 ERROR: Exception on /api/search [GET] [in /mnt/c/Users/willw/Documents/GitHub/projet_photo/microblog/venv/lib/python3.11/site-packages/flask/app.py:1457]
Traceback (most recent call last):
  File "/mnt/c/Users/willw/Documents/GitHub/projet_photo/microblog/venv/lib/python3.11/site-packages/flask/app.py", line 2073, in wsgi_app
    response = self.full_dispatch_request()
               ^^^^^^^^^^^^^^^^^^^^^^^^^^^^
  File "/mnt/c/Users/willw/Documents/GitHub/projet_photo/microblog/venv/lib/python3.11/site-packages/flask/app.py", line 1518, in full_dispatch_request
    rv = self.handle_user_exception(e)
         ^^^^^^^^^^^^^^^^^^^^^^^^^^^^^
  File "/mnt/c/Users/willw/Documents/GitHub/projet_photo/microblog/venv/lib/python3.11/site-packages/flask/app.py", line 1516, in full_dispatch_request
    rv = self.dispatch_request()
         ^^^^^^^^^^^^^^^^^^^^^^^
  File "/mnt/c/Users/willw/Documents/GitHub/projet_photo/microblog/venv/lib/python3.11/site-packages/flask/app.py", line 1502, in dispatch_request
    return self.ensure_sync(self.view_functions[rule.endpoint])(**req.view_args)
           ^^^^^^^^^^^^^^^^^^^^^^^^^^^^^^^^^^^^^^^^^^^^^^^^^^^^^^^^^^^^^^^^^^^^^
  File "/mnt/c/Users/willw/Documents/GitHub/projet_photo/microblog/app/api/routes.py", line 36, in search
    return Response(json.dumps(set(values)),  cls=setEncoder)
                    ^^^^^^^^^^^^^^^^^^^^^^^
  File "/usr/lib/python3.11/json/__init__.py", line 231, in dumps
    return _default_encoder.encode(obj)
           ^^^^^^^^^^^^^^^^^^^^^^^^^^^^
  File "/usr/lib/python3.11/json/encoder.py", line 200, in encode
    chunks = self.iterencode(o, _one_shot=True)
             ^^^^^^^^^^^^^^^^^^^^^^^^^^^^^^^^^^
  File "/usr/lib/python3.11/json/encoder.py", line 258, in iterencode
    return _iterencode(o, 0)
           ^^^^^^^^^^^^^^^^^
  File "/usr/lib/python3.11/json/encoder.py", line 180, in default
    raise TypeError(f'Object of type {o.__class__.__name__} '
TypeError: Object of type set is not JSON serializable
2023-02-09 01:37:06,763 INFO: Microblog startup [in /mnt/c/Users/willw/Documents/GitHub/projet_photo/microblog/app/__init__.py:87]
2023-02-09 01:37:08,970 ERROR: Exception on /api/search [GET] [in /mnt/c/Users/willw/Documents/GitHub/projet_photo/microblog/venv/lib/python3.11/site-packages/flask/app.py:1457]
Traceback (most recent call last):
  File "/mnt/c/Users/willw/Documents/GitHub/projet_photo/microblog/venv/lib/python3.11/site-packages/flask/app.py", line 2073, in wsgi_app
    response = self.full_dispatch_request()
               ^^^^^^^^^^^^^^^^^^^^^^^^^^^^
  File "/mnt/c/Users/willw/Documents/GitHub/projet_photo/microblog/venv/lib/python3.11/site-packages/flask/app.py", line 1518, in full_dispatch_request
    rv = self.handle_user_exception(e)
         ^^^^^^^^^^^^^^^^^^^^^^^^^^^^^
  File "/mnt/c/Users/willw/Documents/GitHub/projet_photo/microblog/venv/lib/python3.11/site-packages/flask/app.py", line 1516, in full_dispatch_request
    rv = self.dispatch_request()
         ^^^^^^^^^^^^^^^^^^^^^^^
  File "/mnt/c/Users/willw/Documents/GitHub/projet_photo/microblog/venv/lib/python3.11/site-packages/flask/app.py", line 1502, in dispatch_request
    return self.ensure_sync(self.view_functions[rule.endpoint])(**req.view_args)
           ^^^^^^^^^^^^^^^^^^^^^^^^^^^^^^^^^^^^^^^^^^^^^^^^^^^^^^^^^^^^^^^^^^^^^
  File "/mnt/c/Users/willw/Documents/GitHub/projet_photo/microblog/app/api/routes.py", line 36, in search
    return Response(json.dumps(values), mimetype='application/json')
                    ^^^^^^^^^^^^^^^^^^
  File "/usr/lib/python3.11/json/__init__.py", line 231, in dumps
    return _default_encoder.encode(obj)
           ^^^^^^^^^^^^^^^^^^^^^^^^^^^^
  File "/usr/lib/python3.11/json/encoder.py", line 200, in encode
    chunks = self.iterencode(o, _one_shot=True)
             ^^^^^^^^^^^^^^^^^^^^^^^^^^^^^^^^^^
  File "/usr/lib/python3.11/json/encoder.py", line 258, in iterencode
    return _iterencode(o, 0)
           ^^^^^^^^^^^^^^^^^
  File "/usr/lib/python3.11/json/encoder.py", line 180, in default
    raise TypeError(f'Object of type {o.__class__.__name__} '
TypeError: Object of type set is not JSON serializable
