2025-02-21 20:59:25,315 ERROR: Exception on /index [POST] [in /mnt/c/Users/willw/Documents/GitHub/projet_photo/microblog/venv/lib/python3.10/site-packages/flask/app.py:1457]
Traceback (most recent call last):
  File "/mnt/c/Users/willw/Documents/GitHub/projet_photo/microblog/venv/lib/python3.10/site-packages/flask/app.py", line 2073, in wsgi_app
    response = self.full_dispatch_request()
  File "/mnt/c/Users/willw/Documents/GitHub/projet_photo/microblog/venv/lib/python3.10/site-packages/flask/app.py", line 1518, in full_dispatch_request
    rv = self.handle_user_exception(e)
  File "/mnt/c/Users/willw/Documents/GitHub/projet_photo/microblog/venv/lib/python3.10/site-packages/flask/app.py", line 1516, in full_dispatch_request
    rv = self.dispatch_request()
  File "/mnt/c/Users/willw/Documents/GitHub/projet_photo/microblog/venv/lib/python3.10/site-packages/flask/app.py", line 1502, in dispatch_request
    return self.ensure_sync(self.view_functions[rule.endpoint])(**req.view_args)
  File "/mnt/c/Users/willw/Documents/GitHub/projet_photo/microblog/venv/lib/python3.10/site-packages/flask_login/utils.py", line 272, in decorated_view
    return func(*args, **kwargs)
  File "/mnt/c/Users/willw/Documents/GitHub/projet_photo/microblog/app/main/routes.py", line 40, in index
    db.session.commit()
  File "<string>", line 2, in commit
  File "/mnt/c/Users/willw/Documents/GitHub/projet_photo/microblog/venv/lib/python3.10/site-packages/sqlalchemy/orm/session.py", line 1451, in commit
    self._transaction.commit(_to_root=self.future)
  File "/mnt/c/Users/willw/Documents/GitHub/projet_photo/microblog/venv/lib/python3.10/site-packages/sqlalchemy/orm/session.py", line 839, in commit
    self.session.dispatch.after_commit(self.session)
  File "/mnt/c/Users/willw/Documents/GitHub/projet_photo/microblog/venv/lib/python3.10/site-packages/sqlalchemy/event/attr.py", line 247, in __call__
    fn(*args, **kw)
  File "/mnt/c/Users/willw/Documents/GitHub/projet_photo/microblog/app/models.py", line 162, in after_commit
    add_to_index(obj.__tablename__, obj)
  File "/mnt/c/Users/willw/Documents/GitHub/projet_photo/microblog/app/search.py", line 30, in add_to_index
    current_app.elasticsearch.index(index=index, id=model.id, body=payload)
  File "/mnt/c/Users/willw/Documents/GitHub/projet_photo/microblog/venv/lib/python3.10/site-packages/elasticsearch/_sync/client/utils.py", line 414, in wrapped
    return api(*args, **kwargs)
  File "/mnt/c/Users/willw/Documents/GitHub/projet_photo/microblog/venv/lib/python3.10/site-packages/elasticsearch/_sync/client/__init__.py", line 2265, in index
    return self.perform_request(  # type: ignore[return-value]
  File "/mnt/c/Users/willw/Documents/GitHub/projet_photo/microblog/venv/lib/python3.10/site-packages/elasticsearch/_sync/client/_base.py", line 286, in perform_request
    meta, resp_body = self.transport.perform_request(
  File "/mnt/c/Users/willw/Documents/GitHub/projet_photo/microblog/venv/lib/python3.10/site-packages/elastic_transport/_transport.py", line 329, in perform_request
    meta, raw_data = node.perform_request(
  File "/mnt/c/Users/willw/Documents/GitHub/projet_photo/microblog/venv/lib/python3.10/site-packages/elastic_transport/_node/_http_urllib3.py", line 199, in perform_request
    raise err from None
elastic_transport.ConnectionError: Connection error caused by: ConnectionError(Connection error caused by: NewConnectionError(<urllib3.connection.HTTPConnection object at 0x7fa7bdc4a200>: Failed to establish a new connection: [Errno 111] Connection refused))
2025-02-21 21:00:09,952 ERROR: Exception on /index [POST] [in /mnt/c/Users/willw/Documents/GitHub/projet_photo/microblog/venv/lib/python3.10/site-packages/flask/app.py:1457]
Traceback (most recent call last):
  File "/mnt/c/Users/willw/Documents/GitHub/projet_photo/microblog/venv/lib/python3.10/site-packages/flask/app.py", line 2073, in wsgi_app
    response = self.full_dispatch_request()
  File "/mnt/c/Users/willw/Documents/GitHub/projet_photo/microblog/venv/lib/python3.10/site-packages/flask/app.py", line 1518, in full_dispatch_request
    rv = self.handle_user_exception(e)
  File "/mnt/c/Users/willw/Documents/GitHub/projet_photo/microblog/venv/lib/python3.10/site-packages/flask/app.py", line 1516, in full_dispatch_request
    rv = self.dispatch_request()
  File "/mnt/c/Users/willw/Documents/GitHub/projet_photo/microblog/venv/lib/python3.10/site-packages/flask/app.py", line 1502, in dispatch_request
    return self.ensure_sync(self.view_functions[rule.endpoint])(**req.view_args)
  File "/mnt/c/Users/willw/Documents/GitHub/projet_photo/microblog/venv/lib/python3.10/site-packages/flask_login/utils.py", line 272, in decorated_view
    return func(*args, **kwargs)
  File "/mnt/c/Users/willw/Documents/GitHub/projet_photo/microblog/app/main/routes.py", line 40, in index
    db.session.commit()
  File "<string>", line 2, in commit
  File "/mnt/c/Users/willw/Documents/GitHub/projet_photo/microblog/venv/lib/python3.10/site-packages/sqlalchemy/orm/session.py", line 1451, in commit
    self._transaction.commit(_to_root=self.future)
  File "/mnt/c/Users/willw/Documents/GitHub/projet_photo/microblog/venv/lib/python3.10/site-packages/sqlalchemy/orm/session.py", line 839, in commit
    self.session.dispatch.after_commit(self.session)
  File "/mnt/c/Users/willw/Documents/GitHub/projet_photo/microblog/venv/lib/python3.10/site-packages/sqlalchemy/event/attr.py", line 247, in __call__
    fn(*args, **kw)
  File "/mnt/c/Users/willw/Documents/GitHub/projet_photo/microblog/app/models.py", line 162, in after_commit
    add_to_index(obj.__tablename__, obj)
  File "/mnt/c/Users/willw/Documents/GitHub/projet_photo/microblog/app/search.py", line 30, in add_to_index
    current_app.elasticsearch.index(index=index, id=model.id, body=payload)
  File "/mnt/c/Users/willw/Documents/GitHub/projet_photo/microblog/venv/lib/python3.10/site-packages/elasticsearch/_sync/client/utils.py", line 414, in wrapped
    return api(*args, **kwargs)
  File "/mnt/c/Users/willw/Documents/GitHub/projet_photo/microblog/venv/lib/python3.10/site-packages/elasticsearch/_sync/client/__init__.py", line 2265, in index
    return self.perform_request(  # type: ignore[return-value]
  File "/mnt/c/Users/willw/Documents/GitHub/projet_photo/microblog/venv/lib/python3.10/site-packages/elasticsearch/_sync/client/_base.py", line 286, in perform_request
    meta, resp_body = self.transport.perform_request(
  File "/mnt/c/Users/willw/Documents/GitHub/projet_photo/microblog/venv/lib/python3.10/site-packages/elastic_transport/_transport.py", line 329, in perform_request
    meta, raw_data = node.perform_request(
  File "/mnt/c/Users/willw/Documents/GitHub/projet_photo/microblog/venv/lib/python3.10/site-packages/elastic_transport/_node/_http_urllib3.py", line 199, in perform_request
    raise err from None
elastic_transport.ConnectionError: Connection error caused by: ConnectionError(Connection error caused by: NewConnectionError(<urllib3.connection.HTTPConnection object at 0x7fa7bc093790>: Failed to establish a new connection: [Errno 111] Connection refused))
